<sdf version='1.6'>
  <world name='default'>
    <light name='sun' type='directional'>
      <cast_shadows>1</cast_shadows>
      <pose frame=''>0 0 10 0 -0 0</pose>
      <diffuse>0.8 0.8 0.8 1</diffuse>
      <specular>0.2 0.2 0.2 1</specular>
      <attenuation>
        <range>1000</range>
        <constant>0.9</constant>
        <linear>0.01</linear>
        <quadratic>0.001</quadratic>
      </attenuation>
      <direction>-0.5 0.1 -0.9</direction>
    </light>
    <model name='ground_plane'>
      <static>1</static>
      <link name='link'>
        <collision name='collision'>
          <geometry>
            <plane>
              <normal>0 0 1</normal>
              <size>100 100</size>
            </plane>
          </geometry>
          <surface>
            <friction>
              <ode>
                <mu>100</mu>
                <mu2>50</mu2>
              </ode>
              <torsional>
                <ode/>
              </torsional>
            </friction>
            <contact>
              <ode/>
            </contact>
            <bounce/>
          </surface>
          <max_contacts>10</max_contacts>
        </collision>
        <visual name='visual'>
          <cast_shadows>0</cast_shadows>
          <geometry>
            <plane>
              <normal>0 0 1</normal>
              <size>100 100</size>
            </plane>
          </geometry>
          <material>
            <script>
              <uri>file://media/materials/scripts/gazebo.material</uri>
              <name>Gazebo/Grey</name>
            </script>
          </material>
        </visual>
        <self_collide>0</self_collide>
        <enable_wind>0</enable_wind>
        <kinematic>0</kinematic>
      </link>
    </model>
    <gravity>0 0 -9.8</gravity>
    <magnetic_field>6e-06 2.3e-05 -4.2e-05</magnetic_field>
    <atmosphere type='adiabatic'/>
    <physics name='default_physics' default='0' type='ode'>
      <max_step_size>0.001</max_step_size>
      <real_time_factor>1</real_time_factor>
      <real_time_update_rate>1000</real_time_update_rate>
    </physics>
    <scene>
      <ambient>0.4 0.4 0.4 1</ambient>
      <background>0.7 0.7 0.7 1</background>
      <shadows>1</shadows>
    </scene>
    <audio>
      <device>default</device>
    </audio>
    <wind/>
    <spherical_coordinates>
      <surface_model>EARTH_WGS84</surface_model>
      <latitude_deg>0</latitude_deg>
      <longitude_deg>0</longitude_deg>
      <elevation>0</elevation>
      <heading_deg>0</heading_deg>
    </spherical_coordinates>
    <model name='grey_wall'>
      <static>1</static>
      <link name='link'>
        <pose frame=''>0 0 1.4 0 -0 0</pose>
        <collision name='collision'>
          <geometry>
            <box>
              <size>7.5 0.2 2.8</size>
            </box>
          </geometry>
          <max_contacts>10</max_contacts>
          <surface>
            <contact>
              <ode/>
            </contact>
            <bounce/>
            <friction>
              <torsional>
                <ode/>
              </torsional>
              <ode/>
            </friction>
          </surface>
        </collision>
        <visual name='visual'>
          <cast_shadows>0</cast_shadows>
          <geometry>
            <box>
              <size>7.5 0.2 2.8</size>
            </box>
          </geometry>
          <material>
            <script>
              <uri>model://grey_wall/materials/scripts</uri>
              <uri>model://grey_wall/materials/textures</uri>
              <name>vrc/grey_wall</name>
            </script>
          </material>
        </visual>
        <self_collide>0</self_collide>
        <enable_wind>0</enable_wind>
        <kinematic>0</kinematic>
      </link>
      <pose frame=''>-1.29479 -3.12743 0 0 -0 0</pose>
    </model>
    <model name='hinged_door'>
      <link name='frame'>
        <pose frame=''>0.06 -0.0005 0 0 -0 0</pose>
        <collision name='collision_1'>
          <pose frame=''>-0.025145 -0.03429 1.0541 0 -0 0</pose>
          <geometry>
            <box>
              <size>0.05029 0.06858 2.1082</size>
            </box>
          </geometry>
          <max_contacts>10</max_contacts>
          <surface>
            <contact>
              <ode/>
            </contact>
            <bounce/>
            <friction>
              <torsional>
                <ode/>
              </torsional>
              <ode/>
            </friction>
          </surface>
        </collision>
        <collision name='collision_2'>
          <pose frame=''>-0.025145 0.95631 1.0541 0 -0 0</pose>
          <geometry>
            <box>
              <size>0.05029 0.06858 2.1082</size>
            </box>
          </geometry>
          <max_contacts>10</max_contacts>
          <surface>
            <contact>
              <ode/>
            </contact>
            <bounce/>
            <friction>
              <torsional>
                <ode/>
              </torsional>
              <ode/>
            </friction>
          </surface>
        </collision>
        <collision name='collision_3'>
          <pose frame=''>-0.025145 0.46482 2.07137 0 -0 0</pose>
          <geometry>
            <box>
              <size>0.05029 0.92964 0.07366</size>
            </box>
          </geometry>
          <max_contacts>10</max_contacts>
          <surface>
            <contact>
              <ode/>
            </contact>
            <bounce/>
            <friction>
              <torsional>
                <ode/>
              </torsional>
              <ode/>
            </friction>
          </surface>
        </collision>
        <visual name='visual'>
          <pose frame=''>0 -0.06858 0 0 -0 0</pose>
          <geometry>
            <mesh>
              <uri>model://hinged_door/meshes/frame.dae</uri>
            </mesh>
          </geometry>
        </visual>
        <self_collide>0</self_collide>
        <inertial>
          <inertia>
            <ixx>1</ixx>
            <ixy>0</ixy>
            <ixz>0</ixz>
            <iyy>1</iyy>
            <iyz>0</iyz>
            <izz>1</izz>
          </inertia>
          <mass>1</mass>
        </inertial>
        <enable_wind>0</enable_wind>
        <kinematic>0</kinematic>
      </link>
      <link name='door'>
        <pose frame=''>-0 0 2.04 3.14159 -0 1.57</pose>
        <inertial>
          <mass>41.3256</mass>
          <pose frame=''>0.4569 0.0349 1.016 0 -0 0</pose>
          <inertia>
            <ixx>14.2053</ixx>
            <ixy>0.0004</ixy>
            <ixz>0</ixz>
            <iyy>17.1997</iyy>
            <iyz>0</iyz>
            <izz>3.0298</izz>
          </inertia>
        </inertial>
        <collision name='collision'>
          <pose frame=''>0.4569 0.0349 1.016 0 -0 0</pose>
          <geometry>
            <box>
              <size>0.9144 0.04445 2.032</size>
            </box>
          </geometry>
          <max_contacts>10</max_contacts>
          <surface>
            <contact>
              <ode/>
            </contact>
            <bounce/>
            <friction>
              <torsional>
                <ode/>
              </torsional>
              <ode/>
            </friction>
          </surface>
        </collision>
        <visual name='visual'>
          <pose frame=''>0 -0.06858 0 0 -0 0</pose>
          <geometry>
            <mesh>
              <uri>model://hinged_door/meshes/door.dae</uri>
            </mesh>
          </geometry>
        </visual>
        <self_collide>0</self_collide>
        <enable_wind>0</enable_wind>
        <kinematic>0</kinematic>
      </link>
      <link name='handles'>
        <pose frame=''>0 0.8 1.05 -3.14159 0.001593 -1.57159</pose>
        <collision name='handle1_collision'>
          <pose frame=''>0.015 -0.015 0 -1.57 0 0</pose>
          <geometry>
            <mesh>
              <uri>model://door_handle/meshes/handle.dae</uri>
            </mesh>
          </geometry>
          <max_contacts>10</max_contacts>
          <surface>
            <contact>
              <ode/>
            </contact>
            <bounce/>
            <friction>
              <torsional>
                <ode/>
              </torsional>
              <ode/>
            </friction>
          </surface>
        </collision>
        <visual name='handle1_visual'>
          <pose frame=''>0.015 -0.015 0 -1.57 0 0</pose>
          <geometry>
            <mesh>
              <uri>model://door_handle/meshes/handle.dae</uri>
            </mesh>
          </geometry>
        </visual>
        <collision name='handle2_collision'>
          <pose frame=''>0.015 -0.055 0 1.57 -0 0</pose>
          <geometry>
            <mesh>
              <uri>model://door_handle/meshes/handle.dae</uri>
            </mesh>
          </geometry>
          <max_contacts>10</max_contacts>
          <surface>
            <contact>
              <ode/>
            </contact>
            <bounce/>
            <friction>
              <torsional>
                <ode/>
              </torsional>
              <ode/>
            </friction>
          </surface>
        </collision>
        <visual name='handle2_visual'>
          <pose frame=''>0.015 -0.055 0 1.57 -0 0</pose>
          <geometry>
            <mesh>
              <uri>model://door_handle/meshes/handle.dae</uri>
            </mesh>
          </geometry>
        </visual>
        <self_collide>0</self_collide>
        <inertial>
          <inertia>
            <ixx>1</ixx>
            <ixy>0</ixy>
            <ixz>0</ixz>
            <iyy>1</iyy>
            <iyz>0</iyz>
            <izz>1</izz>
          </inertia>
          <mass>1</mass>
        </inertial>
        <enable_wind>0</enable_wind>
        <kinematic>0</kinematic>
      </link>
      <joint name='handle' type='revolute'>
        <parent>door</parent>
        <child>handles</child>
        <pose frame=''>0.015 0 0 0 -0 0</pose>
        <axis>
          <xyz>1 0 0</xyz>
          <limit>
            <lower>0</lower>
            <upper>1.58</upper>
          </limit>
          <dynamics>
            <damping>0.1</damping>
            <spring_stiffness>0.3</spring_stiffness>
            <spring_reference>0</spring_reference>
          </dynamics>
          <use_parent_model_frame>1</use_parent_model_frame>
        </axis>
        <physics>
          <ode>
            <cfm_damping>1</cfm_damping>
            <limit>
              <cfm>0</cfm>
              <erp>0.2</erp>
            </limit>
          </ode>
        </physics>
      </joint>
      <joint name='hinge' type='revolute'>
        <parent>frame</parent>
        <child>door</child>
        <axis>
          <xyz>0 0 1</xyz>
          <limit>
            <lower>0</lower>
            <upper>1.58</upper>
          </limit>
          <dynamics>
            <damping>1</damping>
            <friction>1</friction>
            <spring_reference>0</spring_reference>
            <spring_stiffness>0</spring_stiffness>
          </dynamics>
          <use_parent_model_frame>1</use_parent_model_frame>
        </axis>
        <physics>
          <ode>
            <cfm_damping>1</cfm_damping>
            <limit>
              <cfm>0</cfm>
              <erp>0.2</erp>
            </limit>
          </ode>
        </physics>
      </joint>
      <joint name='world_joint' type='revolute'>
        <child>frame</child>
        <parent>world</parent>
        <axis>
          <limit>
            <lower>0</lower>
            <upper>0</upper>
          </limit>
          <xyz>0 1 0</xyz>
          <dynamics>
            <damping>1</damping>
            <spring_reference>0</spring_reference>
            <spring_stiffness>0</spring_stiffness>
          </dynamics>
          <use_parent_model_frame>1</use_parent_model_frame>
        </axis>
        <physics>
          <ode>
            <cfm_damping>1</cfm_damping>
            <limit>
              <cfm>0</cfm>
              <erp>0.2</erp>
            </limit>
          </ode>
        </physics>
      </joint>
      <pose frame=''>-4.9871 -2.93176 0 0 -0 0</pose>
    </model>
    <model name='hinged_door_0'>
      <link name='frame'>
        <pose frame=''>0.06 -0.0005 0 0 -0 0</pose>
        <collision name='collision_1'>
          <pose frame=''>-0.025145 -0.03429 1.0541 0 -0 0</pose>
          <geometry>
            <box>
              <size>0.05029 0.06858 2.1082</size>
            </box>
          </geometry>
          <max_contacts>10</max_contacts>
          <surface>
            <contact>
              <ode/>
            </contact>
            <bounce/>
            <friction>
              <torsional>
                <ode/>
              </torsional>
              <ode/>
            </friction>
          </surface>
        </collision>
        <collision name='collision_2'>
          <pose frame=''>-0.025145 0.95631 1.0541 0 -0 0</pose>
          <geometry>
            <box>
              <size>0.05029 0.06858 2.1082</size>
            </box>
          </geometry>
          <max_contacts>10</max_contacts>
          <surface>
            <contact>
              <ode/>
            </contact>
            <bounce/>
            <friction>
              <torsional>
                <ode/>
              </torsional>
              <ode/>
            </friction>
          </surface>
        </collision>
        <collision name='collision_3'>
          <pose frame=''>-0.025145 0.46482 2.07137 0 -0 0</pose>
          <geometry>
            <box>
              <size>0.05029 0.92964 0.07366</size>
            </box>
          </geometry>
          <max_contacts>10</max_contacts>
          <surface>
            <contact>
              <ode/>
            </contact>
            <bounce/>
            <friction>
              <torsional>
                <ode/>
              </torsional>
              <ode/>
            </friction>
          </surface>
        </collision>
        <visual name='visual'>
          <pose frame=''>0 -0.06858 0 0 -0 0</pose>
          <geometry>
            <mesh>
              <uri>model://hinged_door/meshes/frame.dae</uri>
            </mesh>
          </geometry>
        </visual>
        <self_collide>0</self_collide>
        <inertial>
          <inertia>
            <ixx>1</ixx>
            <ixy>0</ixy>
            <ixz>0</ixz>
            <iyy>1</iyy>
            <iyz>0</iyz>
            <izz>1</izz>
          </inertia>
          <mass>1</mass>
        </inertial>
        <enable_wind>0</enable_wind>
        <kinematic>0</kinematic>
      </link>
      <link name='door'>
        <pose frame=''>-0 0 2.04 3.14159 -0 1.57</pose>
        <inertial>
          <mass>41.3256</mass>
          <pose frame=''>0.4569 0.0349 1.016 0 -0 0</pose>
          <inertia>
            <ixx>14.2053</ixx>
            <ixy>0.0004</ixy>
            <ixz>0</ixz>
            <iyy>17.1997</iyy>
            <iyz>0</iyz>
            <izz>3.0298</izz>
          </inertia>
        </inertial>
        <collision name='collision'>
          <pose frame=''>0.4569 0.0349 1.016 0 -0 0</pose>
          <geometry>
            <box>
              <size>0.9144 0.04445 2.032</size>
            </box>
          </geometry>
          <max_contacts>10</max_contacts>
          <surface>
            <contact>
              <ode/>
            </contact>
            <bounce/>
            <friction>
              <torsional>
                <ode/>
              </torsional>
              <ode/>
            </friction>
          </surface>
        </collision>
        <visual name='visual'>
          <pose frame=''>0 -0.06858 0 0 -0 0</pose>
          <geometry>
            <mesh>
              <uri>model://hinged_door/meshes/door.dae</uri>
            </mesh>
          </geometry>
        </visual>
        <self_collide>0</self_collide>
        <enable_wind>0</enable_wind>
        <kinematic>0</kinematic>
      </link>
      <link name='handles'>
        <pose frame=''>0 0.8 1.05 -3.14159 0.001593 -1.57159</pose>
        <collision name='handle1_collision'>
          <pose frame=''>0.015 -0.015 0 -1.57 0 0</pose>
          <geometry>
            <mesh>
              <uri>model://door_handle/meshes/handle.dae</uri>
            </mesh>
          </geometry>
          <max_contacts>10</max_contacts>
          <surface>
            <contact>
              <ode/>
            </contact>
            <bounce/>
            <friction>
              <torsional>
                <ode/>
              </torsional>
              <ode/>
            </friction>
          </surface>
        </collision>
        <visual name='handle1_visual'>
          <pose frame=''>0.015 -0.015 0 -1.57 0 0</pose>
          <geometry>
            <mesh>
              <uri>model://door_handle/meshes/handle.dae</uri>
            </mesh>
          </geometry>
        </visual>
        <collision name='handle2_collision'>
          <pose frame=''>0.015 -0.055 0 1.57 -0 0</pose>
          <geometry>
            <mesh>
              <uri>model://door_handle/meshes/handle.dae</uri>
            </mesh>
          </geometry>
          <max_contacts>10</max_contacts>
          <surface>
            <contact>
              <ode/>
            </contact>
            <bounce/>
            <friction>
              <torsional>
                <ode/>
              </torsional>
              <ode/>
            </friction>
          </surface>
        </collision>
        <visual name='handle2_visual'>
          <pose frame=''>0.015 -0.055 0 1.57 -0 0</pose>
          <geometry>
            <mesh>
              <uri>model://door_handle/meshes/handle.dae</uri>
            </mesh>
          </geometry>
        </visual>
        <self_collide>0</self_collide>
        <inertial>
          <inertia>
            <ixx>1</ixx>
            <ixy>0</ixy>
            <ixz>0</ixz>
            <iyy>1</iyy>
            <iyz>0</iyz>
            <izz>1</izz>
          </inertia>
          <mass>1</mass>
        </inertial>
        <enable_wind>0</enable_wind>
        <kinematic>0</kinematic>
      </link>
      <joint name='handle' type='revolute'>
        <parent>door</parent>
        <child>handles</child>
        <pose frame=''>0.015 0 0 0 -0 0</pose>
        <axis>
          <xyz>1 0 0</xyz>
          <limit>
            <lower>0</lower>
            <upper>1.58</upper>
          </limit>
          <dynamics>
            <damping>0.1</damping>
            <spring_stiffness>0.3</spring_stiffness>
            <spring_reference>0</spring_reference>
          </dynamics>
          <use_parent_model_frame>1</use_parent_model_frame>
        </axis>
        <physics>
          <ode>
            <cfm_damping>1</cfm_damping>
            <limit>
              <cfm>0</cfm>
              <erp>0.2</erp>
            </limit>
          </ode>
        </physics>
      </joint>
      <joint name='hinge' type='revolute'>
        <parent>frame</parent>
        <child>door</child>
        <axis>
          <xyz>0 0 1</xyz>
          <limit>
            <lower>0</lower>
            <upper>1.58</upper>
          </limit>
          <dynamics>
            <damping>1</damping>
            <friction>1</friction>
            <spring_reference>0</spring_reference>
            <spring_stiffness>0</spring_stiffness>
          </dynamics>
          <use_parent_model_frame>1</use_parent_model_frame>
        </axis>
        <physics>
          <ode>
            <cfm_damping>1</cfm_damping>
            <limit>
              <cfm>0</cfm>
              <erp>0.2</erp>
            </limit>
          </ode>
        </physics>
      </joint>
      <joint name='world_joint' type='revolute'>
        <child>frame</child>
        <parent>world</parent>
        <axis>
          <limit>
            <lower>0</lower>
            <upper>0</upper>
          </limit>
          <xyz>0 1 0</xyz>
          <dynamics>
            <damping>1</damping>
            <spring_reference>0</spring_reference>
            <spring_stiffness>0</spring_stiffness>
          </dynamics>
          <use_parent_model_frame>1</use_parent_model_frame>
        </axis>
        <physics>
          <ode>
            <cfm_damping>1</cfm_damping>
            <limit>
              <cfm>0</cfm>
              <erp>0.2</erp>
            </limit>
          </ode>
        </physics>
      </joint>
      <pose frame=''>-5.00999 -1.85501 0 0 -0 0</pose>
    </model>
    <model name='hinged_door_1'>
      <link name='frame'>
        <pose frame=''>0.06 -0.0005 0 0 -0 0</pose>
        <collision name='collision_1'>
          <pose frame=''>-0.025145 -0.03429 1.0541 0 -0 0</pose>
          <geometry>
            <box>
              <size>0.05029 0.06858 2.1082</size>
            </box>
          </geometry>
          <max_contacts>10</max_contacts>
          <surface>
            <contact>
              <ode/>
            </contact>
            <bounce/>
            <friction>
              <torsional>
                <ode/>
              </torsional>
              <ode/>
            </friction>
          </surface>
        </collision>
        <collision name='collision_2'>
          <pose frame=''>-0.025145 0.95631 1.0541 0 -0 0</pose>
          <geometry>
            <box>
              <size>0.05029 0.06858 2.1082</size>
            </box>
          </geometry>
          <max_contacts>10</max_contacts>
          <surface>
            <contact>
              <ode/>
            </contact>
            <bounce/>
            <friction>
              <torsional>
                <ode/>
              </torsional>
              <ode/>
            </friction>
          </surface>
        </collision>
        <collision name='collision_3'>
          <pose frame=''>-0.025145 0.46482 2.07137 0 -0 0</pose>
          <geometry>
            <box>
              <size>0.05029 0.92964 0.07366</size>
            </box>
          </geometry>
          <max_contacts>10</max_contacts>
          <surface>
            <contact>
              <ode/>
            </contact>
            <bounce/>
            <friction>
              <torsional>
                <ode/>
              </torsional>
              <ode/>
            </friction>
          </surface>
        </collision>
        <visual name='visual'>
          <pose frame=''>0 -0.06858 0 0 -0 0</pose>
          <geometry>
            <mesh>
              <uri>model://hinged_door/meshes/frame.dae</uri>
            </mesh>
          </geometry>
        </visual>
        <self_collide>0</self_collide>
        <inertial>
          <inertia>
            <ixx>1</ixx>
            <ixy>0</ixy>
            <ixz>0</ixz>
            <iyy>1</iyy>
            <iyz>0</iyz>
            <izz>1</izz>
          </inertia>
          <mass>1</mass>
        </inertial>
        <enable_wind>0</enable_wind>
        <kinematic>0</kinematic>
      </link>
      <link name='door'>
        <pose frame=''>-0 0 2.04 3.14159 -0 1.57</pose>
        <inertial>
          <mass>41.3256</mass>
          <pose frame=''>0.4569 0.0349 1.016 0 -0 0</pose>
          <inertia>
            <ixx>14.2053</ixx>
            <ixy>0.0004</ixy>
            <ixz>0</ixz>
            <iyy>17.1997</iyy>
            <iyz>0</iyz>
            <izz>3.0298</izz>
          </inertia>
        </inertial>
        <collision name='collision'>
          <pose frame=''>0.4569 0.0349 1.016 0 -0 0</pose>
          <geometry>
            <box>
              <size>0.9144 0.04445 2.032</size>
            </box>
          </geometry>
          <max_contacts>10</max_contacts>
          <surface>
            <contact>
              <ode/>
            </contact>
            <bounce/>
            <friction>
              <torsional>
                <ode/>
              </torsional>
              <ode/>
            </friction>
          </surface>
        </collision>
        <visual name='visual'>
          <pose frame=''>0 -0.06858 0 0 -0 0</pose>
          <geometry>
            <mesh>
              <uri>model://hinged_door/meshes/door.dae</uri>
            </mesh>
          </geometry>
        </visual>
        <self_collide>0</self_collide>
        <enable_wind>0</enable_wind>
        <kinematic>0</kinematic>
      </link>
      <link name='handles'>
        <pose frame=''>0 0.8 1.05 -3.14159 0.001593 -1.57159</pose>
        <collision name='handle1_collision'>
          <pose frame=''>0.015 -0.015 0 -1.57 0 0</pose>
          <geometry>
            <mesh>
              <uri>model://door_handle/meshes/handle.dae</uri>
            </mesh>
          </geometry>
          <max_contacts>10</max_contacts>
          <surface>
            <contact>
              <ode/>
            </contact>
            <bounce/>
            <friction>
              <torsional>
                <ode/>
              </torsional>
              <ode/>
            </friction>
          </surface>
        </collision>
        <visual name='handle1_visual'>
          <pose frame=''>0.015 -0.015 0 -1.57 0 0</pose>
          <geometry>
            <mesh>
              <uri>model://door_handle/meshes/handle.dae</uri>
            </mesh>
          </geometry>
        </visual>
        <collision name='handle2_collision'>
          <pose frame=''>0.015 -0.055 0 1.57 -0 0</pose>
          <geometry>
            <mesh>
              <uri>model://door_handle/meshes/handle.dae</uri>
            </mesh>
          </geometry>
          <max_contacts>10</max_contacts>
          <surface>
            <contact>
              <ode/>
            </contact>
            <bounce/>
            <friction>
              <torsional>
                <ode/>
              </torsional>
              <ode/>
            </friction>
          </surface>
        </collision>
        <visual name='handle2_visual'>
          <pose frame=''>0.015 -0.055 0 1.57 -0 0</pose>
          <geometry>
            <mesh>
              <uri>model://door_handle/meshes/handle.dae</uri>
            </mesh>
          </geometry>
        </visual>
        <self_collide>0</self_collide>
        <inertial>
          <inertia>
            <ixx>1</ixx>
            <ixy>0</ixy>
            <ixz>0</ixz>
            <iyy>1</iyy>
            <iyz>0</iyz>
            <izz>1</izz>
          </inertia>
          <mass>1</mass>
        </inertial>
        <enable_wind>0</enable_wind>
        <kinematic>0</kinematic>
      </link>
      <joint name='handle' type='revolute'>
        <parent>door</parent>
        <child>handles</child>
        <pose frame=''>0.015 0 0 0 -0 0</pose>
        <axis>
          <xyz>1 0 0</xyz>
          <limit>
            <lower>0</lower>
            <upper>1.58</upper>
          </limit>
          <dynamics>
            <damping>0.1</damping>
            <spring_stiffness>0.3</spring_stiffness>
            <spring_reference>0</spring_reference>
          </dynamics>
          <use_parent_model_frame>1</use_parent_model_frame>
        </axis>
        <physics>
          <ode>
            <cfm_damping>1</cfm_damping>
            <limit>
              <cfm>0</cfm>
              <erp>0.2</erp>
            </limit>
          </ode>
        </physics>
      </joint>
      <joint name='hinge' type='revolute'>
        <parent>frame</parent>
        <child>door</child>
        <axis>
          <xyz>0 0 1</xyz>
          <limit>
            <lower>0</lower>
            <upper>1.58</upper>
          </limit>
          <dynamics>
            <damping>1</damping>
            <friction>1</friction>
            <spring_reference>0</spring_reference>
            <spring_stiffness>0</spring_stiffness>
          </dynamics>
          <use_parent_model_frame>1</use_parent_model_frame>
        </axis>
        <physics>
          <ode>
            <cfm_damping>1</cfm_damping>
            <limit>
              <cfm>0</cfm>
              <erp>0.2</erp>
            </limit>
          </ode>
        </physics>
      </joint>
      <joint name='world_joint' type='revolute'>
        <child>frame</child>
        <parent>world</parent>
        <axis>
          <limit>
            <lower>0</lower>
            <upper>0</upper>
          </limit>
          <xyz>0 1 0</xyz>
          <dynamics>
            <damping>1</damping>
            <spring_reference>0</spring_reference>
            <spring_stiffness>0</spring_stiffness>
          </dynamics>
          <use_parent_model_frame>1</use_parent_model_frame>
        </axis>
        <physics>
          <ode>
            <cfm_damping>1</cfm_damping>
            <limit>
              <cfm>0</cfm>
              <erp>0.2</erp>
            </limit>
          </ode>
        </physics>
      </joint>
      <pose frame=''>-4.99998 -0.779168 0 0 -0 0</pose>
    </model>
    <model name='hinged_door_2'>
      <link name='frame'>
        <pose frame=''>0.06 -0.0005 0 0 -0 0</pose>
        <collision name='collision_1'>
          <pose frame=''>-0.025145 -0.03429 1.0541 0 -0 0</pose>
          <geometry>
            <box>
              <size>0.05029 0.06858 2.1082</size>
            </box>
          </geometry>
          <max_contacts>10</max_contacts>
          <surface>
            <contact>
              <ode/>
            </contact>
            <bounce/>
            <friction>
              <torsional>
                <ode/>
              </torsional>
              <ode/>
            </friction>
          </surface>
        </collision>
        <collision name='collision_2'>
          <pose frame=''>-0.025145 0.95631 1.0541 0 -0 0</pose>
          <geometry>
            <box>
              <size>0.05029 0.06858 2.1082</size>
            </box>
          </geometry>
          <max_contacts>10</max_contacts>
          <surface>
            <contact>
              <ode/>
            </contact>
            <bounce/>
            <friction>
              <torsional>
                <ode/>
              </torsional>
              <ode/>
            </friction>
          </surface>
        </collision>
        <collision name='collision_3'>
          <pose frame=''>-0.025145 0.46482 2.07137 0 -0 0</pose>
          <geometry>
            <box>
              <size>0.05029 0.92964 0.07366</size>
            </box>
          </geometry>
          <max_contacts>10</max_contacts>
          <surface>
            <contact>
              <ode/>
            </contact>
            <bounce/>
            <friction>
              <torsional>
                <ode/>
              </torsional>
              <ode/>
            </friction>
          </surface>
        </collision>
        <visual name='visual'>
          <pose frame=''>0 -0.06858 0 0 -0 0</pose>
          <geometry>
            <mesh>
              <uri>model://hinged_door/meshes/frame.dae</uri>
            </mesh>
          </geometry>
        </visual>
        <self_collide>0</self_collide>
        <inertial>
          <inertia>
            <ixx>1</ixx>
            <ixy>0</ixy>
            <ixz>0</ixz>
            <iyy>1</iyy>
            <iyz>0</iyz>
            <izz>1</izz>
          </inertia>
          <mass>1</mass>
        </inertial>
        <enable_wind>0</enable_wind>
        <kinematic>0</kinematic>
      </link>
      <link name='door'>
        <pose frame=''>-0 0 2.04 3.14159 -0 1.57</pose>
        <inertial>
          <mass>41.3256</mass>
          <pose frame=''>0.4569 0.0349 1.016 0 -0 0</pose>
          <inertia>
            <ixx>14.2053</ixx>
            <ixy>0.0004</ixy>
            <ixz>0</ixz>
            <iyy>17.1997</iyy>
            <iyz>0</iyz>
            <izz>3.0298</izz>
          </inertia>
        </inertial>
        <collision name='collision'>
          <pose frame=''>0.4569 0.0349 1.016 0 -0 0</pose>
          <geometry>
            <box>
              <size>0.9144 0.04445 2.032</size>
            </box>
          </geometry>
          <max_contacts>10</max_contacts>
          <surface>
            <contact>
              <ode/>
            </contact>
            <bounce/>
            <friction>
              <torsional>
                <ode/>
              </torsional>
              <ode/>
            </friction>
          </surface>
        </collision>
        <visual name='visual'>
          <pose frame=''>0 -0.06858 0 0 -0 0</pose>
          <geometry>
            <mesh>
              <uri>model://hinged_door/meshes/door.dae</uri>
            </mesh>
          </geometry>
        </visual>
        <self_collide>0</self_collide>
        <enable_wind>0</enable_wind>
        <kinematic>0</kinematic>
      </link>
      <link name='handles'>
        <pose frame=''>0 0.8 1.05 -3.14159 0.001593 -1.57159</pose>
        <collision name='handle1_collision'>
          <pose frame=''>0.015 -0.015 0 -1.57 0 0</pose>
          <geometry>
            <mesh>
              <uri>model://door_handle/meshes/handle.dae</uri>
            </mesh>
          </geometry>
          <max_contacts>10</max_contacts>
          <surface>
            <contact>
              <ode/>
            </contact>
            <bounce/>
            <friction>
              <torsional>
                <ode/>
              </torsional>
              <ode/>
            </friction>
          </surface>
        </collision>
        <visual name='handle1_visual'>
          <pose frame=''>0.015 -0.015 0 -1.57 0 0</pose>
          <geometry>
            <mesh>
              <uri>model://door_handle/meshes/handle.dae</uri>
            </mesh>
          </geometry>
        </visual>
        <collision name='handle2_collision'>
          <pose frame=''>0.015 -0.055 0 1.57 -0 0</pose>
          <geometry>
            <mesh>
              <uri>model://door_handle/meshes/handle.dae</uri>
            </mesh>
          </geometry>
          <max_contacts>10</max_contacts>
          <surface>
            <contact>
              <ode/>
            </contact>
            <bounce/>
            <friction>
              <torsional>
                <ode/>
              </torsional>
              <ode/>
            </friction>
          </surface>
        </collision>
        <visual name='handle2_visual'>
          <pose frame=''>0.015 -0.055 0 1.57 -0 0</pose>
          <geometry>
            <mesh>
              <uri>model://door_handle/meshes/handle.dae</uri>
            </mesh>
          </geometry>
        </visual>
        <self_collide>0</self_collide>
        <inertial>
          <inertia>
            <ixx>1</ixx>
            <ixy>0</ixy>
            <ixz>0</ixz>
            <iyy>1</iyy>
            <iyz>0</iyz>
            <izz>1</izz>
          </inertia>
          <mass>1</mass>
        </inertial>
        <enable_wind>0</enable_wind>
        <kinematic>0</kinematic>
      </link>
      <joint name='handle' type='revolute'>
        <parent>door</parent>
        <child>handles</child>
        <pose frame=''>0.015 0 0 0 -0 0</pose>
        <axis>
          <xyz>1 0 0</xyz>
          <limit>
            <lower>0</lower>
            <upper>1.58</upper>
          </limit>
          <dynamics>
            <damping>0.1</damping>
            <spring_stiffness>0.3</spring_stiffness>
            <spring_reference>0</spring_reference>
          </dynamics>
          <use_parent_model_frame>1</use_parent_model_frame>
        </axis>
        <physics>
          <ode>
            <cfm_damping>1</cfm_damping>
            <limit>
              <cfm>0</cfm>
              <erp>0.2</erp>
            </limit>
          </ode>
        </physics>
      </joint>
      <joint name='hinge' type='revolute'>
        <parent>frame</parent>
        <child>door</child>
        <axis>
          <xyz>0 0 1</xyz>
          <limit>
            <lower>0</lower>
            <upper>1.58</upper>
          </limit>
          <dynamics>
            <damping>1</damping>
            <friction>1</friction>
            <spring_reference>0</spring_reference>
            <spring_stiffness>0</spring_stiffness>
          </dynamics>
          <use_parent_model_frame>1</use_parent_model_frame>
        </axis>
        <physics>
          <ode>
            <cfm_damping>1</cfm_damping>
            <limit>
              <cfm>0</cfm>
              <erp>0.2</erp>
            </limit>
          </ode>
        </physics>
      </joint>
      <joint name='world_joint' type='revolute'>
        <child>frame</child>
        <parent>world</parent>
        <axis>
          <limit>
            <lower>0</lower>
            <upper>0</upper>
          </limit>
          <xyz>0 1 0</xyz>
          <dynamics>
            <damping>1</damping>
            <spring_reference>0</spring_reference>
            <spring_stiffness>0</spring_stiffness>
          </dynamics>
          <use_parent_model_frame>1</use_parent_model_frame>
        </axis>
        <physics>
          <ode>
            <cfm_damping>1</cfm_damping>
            <limit>
              <cfm>0</cfm>
              <erp>0.2</erp>
            </limit>
          </ode>
        </physics>
      </joint>
      <pose frame=''>-5.0011 0.29879 0 0 -0 0</pose>
    </model>
    <model name='hinged_door_3'>
      <link name='frame'>
        <pose frame=''>0.06 -0.0005 0 0 -0 0</pose>
        <collision name='collision_1'>
          <pose frame=''>-0.025145 -0.03429 1.0541 0 -0 0</pose>
          <geometry>
            <box>
              <size>0.05029 0.06858 2.1082</size>
            </box>
          </geometry>
          <max_contacts>10</max_contacts>
          <surface>
            <contact>
              <ode/>
            </contact>
            <bounce/>
            <friction>
              <torsional>
                <ode/>
              </torsional>
              <ode/>
            </friction>
          </surface>
        </collision>
        <collision name='collision_2'>
          <pose frame=''>-0.025145 0.95631 1.0541 0 -0 0</pose>
          <geometry>
            <box>
              <size>0.05029 0.06858 2.1082</size>
            </box>
          </geometry>
          <max_contacts>10</max_contacts>
          <surface>
            <contact>
              <ode/>
            </contact>
            <bounce/>
            <friction>
              <torsional>
                <ode/>
              </torsional>
              <ode/>
            </friction>
          </surface>
        </collision>
        <collision name='collision_3'>
          <pose frame=''>-0.025145 0.46482 2.07137 0 -0 0</pose>
          <geometry>
            <box>
              <size>0.05029 0.92964 0.07366</size>
            </box>
          </geometry>
          <max_contacts>10</max_contacts>
          <surface>
            <contact>
              <ode/>
            </contact>
            <bounce/>
            <friction>
              <torsional>
                <ode/>
              </torsional>
              <ode/>
            </friction>
          </surface>
        </collision>
        <visual name='visual'>
          <pose frame=''>0 -0.06858 0 0 -0 0</pose>
          <geometry>
            <mesh>
              <uri>model://hinged_door/meshes/frame.dae</uri>
            </mesh>
          </geometry>
        </visual>
        <self_collide>0</self_collide>
        <inertial>
          <inertia>
            <ixx>1</ixx>
            <ixy>0</ixy>
            <ixz>0</ixz>
            <iyy>1</iyy>
            <iyz>0</iyz>
            <izz>1</izz>
          </inertia>
          <mass>1</mass>
        </inertial>
        <enable_wind>0</enable_wind>
        <kinematic>0</kinematic>
      </link>
      <link name='door'>
        <pose frame=''>-0 0 2.04 3.14159 -0 1.57</pose>
        <inertial>
          <mass>41.3256</mass>
          <pose frame=''>0.4569 0.0349 1.016 0 -0 0</pose>
          <inertia>
            <ixx>14.2053</ixx>
            <ixy>0.0004</ixy>
            <ixz>0</ixz>
            <iyy>17.1997</iyy>
            <iyz>0</iyz>
            <izz>3.0298</izz>
          </inertia>
        </inertial>
        <collision name='collision'>
          <pose frame=''>0.4569 0.0349 1.016 0 -0 0</pose>
          <geometry>
            <box>
              <size>0.9144 0.04445 2.032</size>
            </box>
          </geometry>
          <max_contacts>10</max_contacts>
          <surface>
            <contact>
              <ode/>
            </contact>
            <bounce/>
            <friction>
              <torsional>
                <ode/>
              </torsional>
              <ode/>
            </friction>
          </surface>
        </collision>
        <visual name='visual'>
          <pose frame=''>0 -0.06858 0 0 -0 0</pose>
          <geometry>
            <mesh>
              <uri>model://hinged_door/meshes/door.dae</uri>
            </mesh>
          </geometry>
        </visual>
        <self_collide>0</self_collide>
        <enable_wind>0</enable_wind>
        <kinematic>0</kinematic>
      </link>
      <link name='handles'>
        <pose frame=''>0 0.8 1.05 -3.14159 0.001593 -1.57159</pose>
        <collision name='handle1_collision'>
          <pose frame=''>0.015 -0.015 0 -1.57 0 0</pose>
          <geometry>
            <mesh>
              <uri>model://door_handle/meshes/handle.dae</uri>
            </mesh>
          </geometry>
          <max_contacts>10</max_contacts>
          <surface>
            <contact>
              <ode/>
            </contact>
            <bounce/>
            <friction>
              <torsional>
                <ode/>
              </torsional>
              <ode/>
            </friction>
          </surface>
        </collision>
        <visual name='handle1_visual'>
          <pose frame=''>0.015 -0.015 0 -1.57 0 0</pose>
          <geometry>
            <mesh>
              <uri>model://door_handle/meshes/handle.dae</uri>
            </mesh>
          </geometry>
        </visual>
        <collision name='handle2_collision'>
          <pose frame=''>0.015 -0.055 0 1.57 -0 0</pose>
          <geometry>
            <mesh>
              <uri>model://door_handle/meshes/handle.dae</uri>
            </mesh>
          </geometry>
          <max_contacts>10</max_contacts>
          <surface>
            <contact>
              <ode/>
            </contact>
            <bounce/>
            <friction>
              <torsional>
                <ode/>
              </torsional>
              <ode/>
            </friction>
          </surface>
        </collision>
        <visual name='handle2_visual'>
          <pose frame=''>0.015 -0.055 0 1.57 -0 0</pose>
          <geometry>
            <mesh>
              <uri>model://door_handle/meshes/handle.dae</uri>
            </mesh>
          </geometry>
        </visual>
        <self_collide>0</self_collide>
        <inertial>
          <inertia>
            <ixx>1</ixx>
            <ixy>0</ixy>
            <ixz>0</ixz>
            <iyy>1</iyy>
            <iyz>0</iyz>
            <izz>1</izz>
          </inertia>
          <mass>1</mass>
        </inertial>
        <enable_wind>0</enable_wind>
        <kinematic>0</kinematic>
      </link>
      <joint name='handle' type='revolute'>
        <parent>door</parent>
        <child>handles</child>
        <pose frame=''>0.015 0 0 0 -0 0</pose>
        <axis>
          <xyz>1 0 0</xyz>
          <limit>
            <lower>0</lower>
            <upper>1.58</upper>
          </limit>
          <dynamics>
            <damping>0.1</damping>
            <spring_stiffness>0.3</spring_stiffness>
            <spring_reference>0</spring_reference>
          </dynamics>
          <use_parent_model_frame>1</use_parent_model_frame>
        </axis>
        <physics>
          <ode>
            <cfm_damping>1</cfm_damping>
            <limit>
              <cfm>0</cfm>
              <erp>0.2</erp>
            </limit>
          </ode>
        </physics>
      </joint>
      <joint name='hinge' type='revolute'>
        <parent>frame</parent>
        <child>door</child>
        <axis>
          <xyz>0 0 1</xyz>
          <limit>
            <lower>0</lower>
            <upper>1.58</upper>
          </limit>
          <dynamics>
            <damping>1</damping>
            <friction>1</friction>
            <spring_reference>0</spring_reference>
            <spring_stiffness>0</spring_stiffness>
          </dynamics>
          <use_parent_model_frame>1</use_parent_model_frame>
        </axis>
        <physics>
          <ode>
            <cfm_damping>1</cfm_damping>
            <limit>
              <cfm>0</cfm>
              <erp>0.2</erp>
            </limit>
          </ode>
        </physics>
      </joint>
      <joint name='world_joint' type='revolute'>
        <child>frame</child>
        <parent>world</parent>
        <axis>
          <limit>
            <lower>0</lower>
            <upper>0</upper>
          </limit>
          <xyz>0 1 0</xyz>
          <dynamics>
            <damping>1</damping>
            <spring_reference>0</spring_reference>
            <spring_stiffness>0</spring_stiffness>
          </dynamics>
          <use_parent_model_frame>1</use_parent_model_frame>
        </axis>
        <physics>
          <ode>
            <cfm_damping>1</cfm_damping>
            <limit>
              <cfm>0</cfm>
              <erp>0.2</erp>
            </limit>
          </ode>
        </physics>
      </joint>
      <pose frame=''>-5.00096 1.36334 0 0 -0 0</pose>
    </model>
    <model name='hinged_door_4'>
      <link name='frame'>
        <pose frame=''>0.06 -0.0005 0 0 -0 0</pose>
        <collision name='collision_1'>
          <pose frame=''>-0.025145 -0.03429 1.0541 0 -0 0</pose>
          <geometry>
            <box>
              <size>0.05029 0.06858 2.1082</size>
            </box>
          </geometry>
          <max_contacts>10</max_contacts>
          <surface>
            <contact>
              <ode/>
            </contact>
            <bounce/>
            <friction>
              <torsional>
                <ode/>
              </torsional>
              <ode/>
            </friction>
          </surface>
        </collision>
        <collision name='collision_2'>
          <pose frame=''>-0.025145 0.95631 1.0541 0 -0 0</pose>
          <geometry>
            <box>
              <size>0.05029 0.06858 2.1082</size>
            </box>
          </geometry>
          <max_contacts>10</max_contacts>
          <surface>
            <contact>
              <ode/>
            </contact>
            <bounce/>
            <friction>
              <torsional>
                <ode/>
              </torsional>
              <ode/>
            </friction>
          </surface>
        </collision>
        <collision name='collision_3'>
          <pose frame=''>-0.025145 0.46482 2.07137 0 -0 0</pose>
          <geometry>
            <box>
              <size>0.05029 0.92964 0.07366</size>
            </box>
          </geometry>
          <max_contacts>10</max_contacts>
          <surface>
            <contact>
              <ode/>
            </contact>
            <bounce/>
            <friction>
              <torsional>
                <ode/>
              </torsional>
              <ode/>
            </friction>
          </surface>
        </collision>
        <visual name='visual'>
          <pose frame=''>0 -0.06858 0 0 -0 0</pose>
          <geometry>
            <mesh>
              <uri>model://hinged_door/meshes/frame.dae</uri>
            </mesh>
          </geometry>
        </visual>
        <self_collide>0</self_collide>
        <inertial>
          <inertia>
            <ixx>1</ixx>
            <ixy>0</ixy>
            <ixz>0</ixz>
            <iyy>1</iyy>
            <iyz>0</iyz>
            <izz>1</izz>
          </inertia>
          <mass>1</mass>
        </inertial>
        <enable_wind>0</enable_wind>
        <kinematic>0</kinematic>
      </link>
      <link name='door'>
        <pose frame=''>-0 0 2.04 3.14159 -0 1.57</pose>
        <inertial>
          <mass>41.3256</mass>
          <pose frame=''>0.4569 0.0349 1.016 0 -0 0</pose>
          <inertia>
            <ixx>14.2053</ixx>
            <ixy>0.0004</ixy>
            <ixz>0</ixz>
            <iyy>17.1997</iyy>
            <iyz>0</iyz>
            <izz>3.0298</izz>
          </inertia>
        </inertial>
        <collision name='collision'>
          <pose frame=''>0.4569 0.0349 1.016 0 -0 0</pose>
          <geometry>
            <box>
              <size>0.9144 0.04445 2.032</size>
            </box>
          </geometry>
          <max_contacts>10</max_contacts>
          <surface>
            <contact>
              <ode/>
            </contact>
            <bounce/>
            <friction>
              <torsional>
                <ode/>
              </torsional>
              <ode/>
            </friction>
          </surface>
        </collision>
        <visual name='visual'>
          <pose frame=''>0 -0.06858 0 0 -0 0</pose>
          <geometry>
            <mesh>
              <uri>model://hinged_door/meshes/door.dae</uri>
            </mesh>
          </geometry>
        </visual>
        <self_collide>0</self_collide>
        <enable_wind>0</enable_wind>
        <kinematic>0</kinematic>
      </link>
      <link name='handles'>
        <pose frame=''>0 0.8 1.05 -3.14159 0.001593 -1.57159</pose>
        <collision name='handle1_collision'>
          <pose frame=''>0.015 -0.015 0 -1.57 0 0</pose>
          <geometry>
            <mesh>
              <uri>model://door_handle/meshes/handle.dae</uri>
            </mesh>
          </geometry>
          <max_contacts>10</max_contacts>
          <surface>
            <contact>
              <ode/>
            </contact>
            <bounce/>
            <friction>
              <torsional>
                <ode/>
              </torsional>
              <ode/>
            </friction>
          </surface>
        </collision>
        <visual name='handle1_visual'>
          <pose frame=''>0.015 -0.015 0 -1.57 0 0</pose>
          <geometry>
            <mesh>
              <uri>model://door_handle/meshes/handle.dae</uri>
            </mesh>
          </geometry>
        </visual>
        <collision name='handle2_collision'>
          <pose frame=''>0.015 -0.055 0 1.57 -0 0</pose>
          <geometry>
            <mesh>
              <uri>model://door_handle/meshes/handle.dae</uri>
            </mesh>
          </geometry>
          <max_contacts>10</max_contacts>
          <surface>
            <contact>
              <ode/>
            </contact>
            <bounce/>
            <friction>
              <torsional>
                <ode/>
              </torsional>
              <ode/>
            </friction>
          </surface>
        </collision>
        <visual name='handle2_visual'>
          <pose frame=''>0.015 -0.055 0 1.57 -0 0</pose>
          <geometry>
            <mesh>
              <uri>model://door_handle/meshes/handle.dae</uri>
            </mesh>
          </geometry>
        </visual>
        <self_collide>0</self_collide>
        <inertial>
          <inertia>
            <ixx>1</ixx>
            <ixy>0</ixy>
            <ixz>0</ixz>
            <iyy>1</iyy>
            <iyz>0</iyz>
            <izz>1</izz>
          </inertia>
          <mass>1</mass>
        </inertial>
        <enable_wind>0</enable_wind>
        <kinematic>0</kinematic>
      </link>
      <joint name='handle' type='revolute'>
        <parent>door</parent>
        <child>handles</child>
        <pose frame=''>0.015 0 0 0 -0 0</pose>
        <axis>
          <xyz>1 0 0</xyz>
          <limit>
            <lower>0</lower>
            <upper>1.58</upper>
          </limit>
          <dynamics>
            <damping>0.1</damping>
            <spring_stiffness>0.3</spring_stiffness>
            <spring_reference>0</spring_reference>
          </dynamics>
          <use_parent_model_frame>1</use_parent_model_frame>
        </axis>
        <physics>
          <ode>
            <cfm_damping>1</cfm_damping>
            <limit>
              <cfm>0</cfm>
              <erp>0.2</erp>
            </limit>
          </ode>
        </physics>
      </joint>
      <joint name='hinge' type='revolute'>
        <parent>frame</parent>
        <child>door</child>
        <axis>
          <xyz>0 0 1</xyz>
          <limit>
            <lower>0</lower>
            <upper>1.58</upper>
          </limit>
          <dynamics>
            <damping>1</damping>
            <friction>1</friction>
            <spring_reference>0</spring_reference>
            <spring_stiffness>0</spring_stiffness>
          </dynamics>
          <use_parent_model_frame>1</use_parent_model_frame>
        </axis>
        <physics>
          <ode>
            <cfm_damping>1</cfm_damping>
            <limit>
              <cfm>0</cfm>
              <erp>0.2</erp>
            </limit>
          </ode>
        </physics>
      </joint>
      <joint name='world_joint' type='revolute'>
        <child>frame</child>
        <parent>world</parent>
        <axis>
          <limit>
            <lower>0</lower>
            <upper>0</upper>
          </limit>
          <xyz>0 1 0</xyz>
          <dynamics>
            <damping>1</damping>
            <spring_reference>0</spring_reference>
            <spring_stiffness>0</spring_stiffness>
          </dynamics>
          <use_parent_model_frame>1</use_parent_model_frame>
        </axis>
        <physics>
          <ode>
            <cfm_damping>1</cfm_damping>
            <limit>
              <cfm>0</cfm>
              <erp>0.2</erp>
            </limit>
          </ode>
        </physics>
      </joint>
      <pose frame=''>-5.00515 2.43738 0 0 -0 0</pose>
    </model>
    <state world_name='default'>
      <sim_time>90 934000000</sim_time>
      <real_time>91 523071334</real_time>
      <wall_time>1599058190 114998249</wall_time>
      <iterations>90934</iterations>
      <model name='grey_wall'>
        <pose frame=''>-1.29479 -3.12743 0 0 -0 0</pose>
        <scale>1 1 1</scale>
        <link name='link'>
          <pose frame=''>-1.29479 -3.12743 1.4 0 -0 0</pose>
          <velocity>0 0 0 0 -0 0</velocity>
          <acceleration>0 0 0 0 -0 0</acceleration>
          <wrench>0 0 0 0 -0 0</wrench>
        </link>
      </model>
      <model name='ground_plane'>
        <pose frame=''>0 0 0 0 -0 0</pose>
        <scale>1 1 1</scale>
        <link name='link'>
          <pose frame=''>0 0 0 0 -0 0</pose>
          <velocity>0 0 0 0 -0 0</velocity>
          <acceleration>0 0 0 0 -0 0</acceleration>
          <wrench>0 0 0 0 -0 0</wrench>
        </link>
      </model>
      <model name='hinged_door'>
        <pose frame=''>-4.9871 -2.93176 2e-06 1e-06 -0 0</pose>
        <scale>1 1 1</scale>
        <link name='door'>
          <pose frame=''>-4.9871 -2.93177 2.03999 3.14159 2e-06 1.57659</pose>
          <velocity>-0.000244 5e-06 -4e-06 0 -0.000123 -3.2e-05</velocity>
          <acceleration>-0.118587 -0.000928 2.5e-05 0.000283 -0.333255 -0.316376</acceleration>
          <wrench>-4.90069 -0.03833 0.001038 0 -0 0</wrench>
        </link>
        <link name='frame'>
          <pose frame=''>-4.9271 -2.93226 2e-06 1e-06 -0 0</pose>
          <velocity>-1.7e-05 -0 -1e-06 -0 -0.000249 -5e-06</velocity>
          <acceleration>-0.032828 -0.000551 -0.002169 -0.000494 -0.525839 -0.002511</acceleration>
          <wrench>-0.032828 -0.000551 -0.002169 0 -0 0</wrench>
        </link>
        <link name='handles'>
          <pose frame=''>-4.99237 -2.13179 1.04999 -3.14159 0.001591 -1.565</pose>
          <velocity>-9.9e-05 4e-06 -4e-06 -0 -0.000121 -1.8e-05</velocity>
          <acceleration>-0.020787 0.010312 -0.009978 -0.00017 -0.270284 -0.297106</acceleration>
          <wrench>-0.020787 0.010312 -0.009978 0 -0 0</wrench>
        </link>
      </model>
      <model name='hinged_door_0'>
        <pose frame=''>-5.00999 -1.85501 2e-06 1e-06 -0 0</pose>
        <scale>1 1 1</scale>
        <link name='door'>
          <pose frame=''>-5.00999 -1.85502 2.03999 3.14159 2e-06 1.57561</pose>
          <velocity>-0.00023 6e-06 -3e-06 -1e-06 -0.00012 -1.3e-05</velocity>
          <acceleration>-0.116755 -0.001341 -0.000187 0.000114 -0.336496 -0.326719</acceleration>
          <wrench>-4.82496 -0.055429 -0.007714 0 -0 0</wrench>
        </link>
        <link name='frame'>
          <pose frame=''>-4.94999 -1.85551 2e-06 1e-06 -0 0</pose>
          <velocity>-1.6e-05 -0 -1e-06 0 -0.000245 9e-06</velocity>
          <acceleration>-0.031586 -0.000608 -0.002219 -0.000486 -0.522475 0.013343</acceleration>
          <wrench>-0.031586 -0.000608 -0.002219 0 -0 0</wrench>
        </link>
        <link name='handles'>
          <pose frame=''>-5.01448 -1.05503 1.04999 -3.14159 0.001591 -1.56598</pose>
          <velocity>-9.9e-05 5e-06 -4e-06 -1e-06 -0.000118 -1.5e-05</velocity>
          <acceleration>-0.009593 0.010834 -0.010235 -0.000123 -0.272897 -0.325543</acceleration>
          <wrench>-0.009593 0.010834 -0.010235 0 -0 0</wrench>
        </link>
      </model>
      <model name='hinged_door_1'>
        <pose frame=''>-4.99998 -0.779168 2e-06 1e-06 -0 0</pose>
        <scale>1 1 1</scale>
        <link name='door'>
          <pose frame=''>-4.99998 -0.779176 2.03999 3.14159 2e-06 1.57475</pose>
          <velocity>-0.000245 5e-06 -4e-06 0 -0.000124 -3.2e-05</velocity>
          <acceleration>-0.118597 -0.000925 6.1e-05 -5e-06 -0.333361 -0.316391</acceleration>
          <wrench>-4.90109 -0.038241 0.002536 0 -0 0</wrench>
        </link>
        <link name='frame'>
          <pose frame=''>-4.93998 -0.779668 2e-06 1e-06 -0 0</pose>
          <velocity>-1.7e-05 -0 -1e-06 0 -0.00025 -6e-06</velocity>
          <acceleration>-0.032831 -0.00059 -0.002126 -0.000435 -0.525889 -0.002633</acceleration>
          <wrench>-0.032831 -0.00059 -0.002126 0 -0 0</wrench>
        </link>
        <link name='handles'>
          <pose frame=''>-5.00378 0.020813 1.04999 -3.14159 0.001591 -1.56684</pose>
          <velocity>-0.0001 5e-06 -4e-06 0 -0.000121 -1.7e-05</velocity>
          <acceleration>-0.020858 0.010125 -0.009852 -0.000381 -0.270373 -0.296993</acceleration>
          <wrench>-0.020858 0.010125 -0.009852 0 -0 0</wrench>
        </link>
      </model>
      <model name='hinged_door_2'>
        <pose frame=''>-5.0011 0.29879 2e-06 1e-06 -0 0</pose>
        <scale>1 1 1</scale>
        <link name='door'>
          <pose frame=''>-5.0011 0.298782 2.03999 3.14159 2e-06 1.57376</pose>
          <velocity>-0.000237 5e-06 -3e-06 0 -0.000122 -2.3e-05</velocity>
          <acceleration>-0.118475 -0.000891 -5e-06 -0.000185 -0.334318 -0.312815</acceleration>
          <wrench>-4.89604 -0.036817 -0.000221 0 -0 0</wrench>
        </link>
        <link name='frame'>
          <pose frame=''>-4.9411 0.29829 2e-06 1e-06 -0 0</pose>
          <velocity>-1.6e-05 -0 -1e-06 0 -0.000247 1e-06</velocity>
          <acceleration>-0.03228 -0.000634 -0.002122 -0.00041 -0.523261 0.006406</acceleration>
          <wrench>-0.03228 -0.000634 -0.002122 0 -0 0</wrench>
        </link>
        <link name='handles'>
          <pose frame=''>-5.00411 1.09878 1.04999 -3.14159 0.001591 -1.56783</pose>
          <velocity>-0.0001 4e-06 -4e-06 0 -0.000119 -1.5e-05</velocity>
          <acceleration>-0.018694 0.010286 -0.009904 -0.000337 -0.271186 -0.30366</acceleration>
          <wrench>-0.018694 0.010286 -0.009904 0 -0 0</wrench>
        </link>
      </model>
      <model name='hinged_door_3'>
        <pose frame=''>-5.00096 1.36334 2e-06 1e-06 -0 0</pose>
        <scale>1 1 1</scale>
        <link name='door'>
          <pose frame=''>-5.00096 1.36333 2.03999 3.14159 2e-06 1.5725</pose>
          <velocity>0.000299 -5e-06 5e-06 0 0.000152 0.000286</velocity>
          <acceleration>0.117547 0.000948 -0.000139 0.000332 0.332357 0.308925</acceleration>
          <wrench>4.8577 0.039185 -0.005732 0 -0 0</wrench>
        </link>
        <link name='frame'>
          <pose frame=''>-4.94096 1.36284 2e-06 1e-06 -0 0</pose>
          <velocity>1.6e-05 0 1e-06 0 0.000276 -5e-06</velocity>
          <acceleration>0.03261 0.000641 0.002085 0.000378 0.523464 -0.00512</acceleration>
          <wrench>0.03261 0.000641 0.002085 0 -0 0</wrench>
        </link>
        <link name='handles'>
          <pose frame=''>-5.00296 2.16333 1.04999 -3.14159 0.001591 -1.56909</pose>
          <velocity>-8.1e-05 -5e-06 6e-06 0 0.000149 0.000283</velocity>
          <acceleration>0.019562 -0.009903 0.009618 0.000518 0.269566 0.298192</acceleration>
          <wrench>0.019562 -0.009903 0.009618 0 -0 0</wrench>
        </link>
      </model>
      <model name='hinged_door_4'>
        <pose frame=''>-5.00515 2.43738 2e-06 1e-06 -0 0</pose>
        <scale>1 1 1</scale>
        <link name='door'>
          <pose frame=''>-5.00515 2.43737 2.03999 3.14159 2e-06 1.57126</pose>
          <velocity>0.000331 -8e-06 6e-06 1e-06 0.000161 0.000352</velocity>
          <acceleration>0.129466 0.002495 0.000843 0.000406 0.347718 0.359603</acceleration>
          <wrench>5.35027 0.103116 0.034854 0 -0 0</wrench>
        </link>
        <link name='frame'>
          <pose frame=''>-4.94515 2.43688 2e-06 1e-06 -0 0</pose>
          <velocity>1.4e-05 1e-06 1e-06 0 0.000277 -3e-06</velocity>
          <acceleration>0.029057 0.000677 0.002157 0.00041 0.52025 -0.013887</acceleration>
          <wrench>0.029057 0.000677 0.002157 0 -0 0</wrench>
        </link>
        <link name='handles'>
          <pose frame=''>-5.00616 3.23737 1.04999 -3.14159 0.001591 -1.57033</pose>
          <velocity>-0.000109 -7e-06 7e-06 1e-06 0.000158 0.000347</velocity>
          <acceleration>0.010821 -0.010442 0.010919 0.000261 0.281982 0.360303</acceleration>
          <wrench>0.010821 -0.010442 0.010919 0 -0 0</wrench>
        </link>
      </model>
      <light name='sun'>
        <pose frame=''>0 0 10 0 -0 0</pose>
      </light>
    </state>
    <gui fullscreen='0'>
      <camera name='user_camera'>
        <pose frame=''>9.96495 -1.07776 8.79449 -0 0.555643 3.06819</pose>
        <view_controller>orbit</view_controller>
        <projection_type>perspective</projection_type>
      </camera>
    </gui>
  </world>
</sdf>
